Workbook

Sheet DCF
B1: HDFC AMC COMPANY LTD
A3: x | B3: Ticker | C3: HDFC AMC | E3: Implied Share Price | G3: =N62 -> 2882.5875
B4: Date | C4: 46105 | E4: Today's Share Price | G4: 2314 | I4: Upside | K4: =(G3-G4)/G4 -> 0.24571628
A6: x | B6: Assumptions
B7: Valuation Assumptions
B8: WACC | D8: =WACC!D20 -> 0.1139125
B9: TGR | D9: 0.065
J10: 1 | K10: 2 | L10: 3 | M10: 4 | N10: 5
A11: x | B11: Income Statement | E11: 2021 | F11: 2022 | G11: 2023 | H11: 2024 | I11: 2025 | J11: 2026 | K11: 2027 | L11: 2028 | M11: 2029 | N11: 2030
B12: Revenue | E12: 2194.02 | F12: 2428.72 | G12: 2478.28 | H12: 3158.72 | I12: 4049.61 | J12: =I12*(1+Assumptions!B2) -> 4535.5632 | K12: =J12*(1+Assumptions!B3) -> 5125.1864 | L12: =K12*(1+Assumptions!B4) -> 5791.4607 | M12: =L12*(1+Assumptions!B5) -> 6486.4359 | N12: =M12*(1+Assumptions!B6) -> 7199.9439
B13: % growth | F13: =F12/E12-1 -> 0.10697259 | G13: =G12/F12-1 -> 0.02040581 | H13: =H12/G12-1 -> 0.27456139 | I13: =I12/H12-1 -> 0.28204146 | J13: =J12/I12-1 -> 0.12 | K13: =K12/J12-1 -> 0.13 | L13: =L12/K12-1 -> 0.13 | M13: =M12/L12-1 -> 0.12 | N13: =N12/M12-1 -> 0.11
B15: EBIT | E15: 1805.59 | F15: 1913.3 | G15: 1929.21 | H15: 2535.83 | I15: 3345.61 | J15: =J12*Assumptions!B10 -> 2857.4048 | K15: =K12*Assumptions!B10 -> 3228.8674 | L15: =L12*Assumptions!B10 -> 3648.6202 | M15: =M12*Assumptions!B10 -> 4086.4546 | N15: =N12*Assumptions!B10 -> 4535.9646
B16: % of sales | E16: =E15/E12 -> 0.82295968 | F16: =F15/F12 -> 0.78778122 | G16: =G15/G12 -> 0.77844715 | H16: =H15/H12 -> 0.80280303 | I16: =I15/I12 -> 0.8261561 | J16: =J15/J12 -> 0.63 | K16: =K15/K12 -> 0.63 | L16: =L15/L12 -> 0.63 | ... N16: =N15/N12 -> 0.63
B18: Taxes | E18: 423.19 | F18: 426.16 | G18: 446.69 | H18: 532.31 | I18: 825.39 | J18: =J15*Assumptions!B12 -> 714.3512 | K18: =K15*Assumptions!B12 -> 807.21686 | L18: =L15*Assumptions!B12 -> 912.15505 | M18: =M15*Assumptions!B12 -> 1021.6137 | N18: =N15*Assumptions!B12 -> 1133.9912
B19: % of EBIT | E19: =E18/E15 -> 0.23437768 | F19: =F18/F15 -> 0.22273559 | G19: =G18/G15 -> 0.23154037 | H19: =H18/H15 -> 0.20991549 | I19: =I18/I15 -> 0.24670837 | J19: =J18/J15 -> 0.25 | K19: =K18/K15 -> 0.25 | L19: =L18/L15 -> 0.25 | ... N19: =N18/N15 -> 0.25
A21: x | B21: Cash Flow Items | E21: 2021 | F21: 2022 | G21: 2023 | H21: 2024 | I21: 2025 | J21: 2026 | K21: 2027 | L21: 2028 | M21: 2029 | N21: 2030
B22: D&A | E22: 55.41 | F22: 53.85 | G22: 53.34 | H22: 52.26 | I22: 58.41 | J22: =J12*Assumptions!B11 -> 90.711264 | K22: =K12*Assumptions!B11 -> 102.50373 | L22: =L12*Assumptions!B11 -> 115.82921 | M22: =M12*Assumptions!B11 -> 129.72872 | N22: =N12*Assumptions!B11 -> 143.99888
B23: % of sales | E23: =E22/E12 -> 0.025255011 | F23: =F22/F12 -> 0.022172173 | G23: =G22/G12 -> 0.021522992 | H23: =H22/H12 -> 0.016544676 | I23: =I22/I12 -> 0.014423611 | J23: =J22/J12 -> 0.02 | K23: =K22/K12 -> 0.02 | L23: =L22/L12 -> 0.02 | ... N23: =N22/N12 -> 0.02
B25: CapEx | E25: -12 | F25: -10 | G25: -14 | H25: -19 | I25: -45 | J25: =J12*Assumptions!B13 -> 90.711264 | K25: =K12*Assumptions!B13 -> 102.50373 | L25: =L12*Assumptions!B13 -> 115.82921 | M25: =M12*Assumptions!B13 -> 129.72872 | N25: =N12*Assumptions!B13 -> 143.99888
B26: % of sales | E26: =E25/E12 -> -0.0054694123 | F26: =F25/F12 -> -0.0041173952 | G26: =G25/G12 -> -0.0056490792 | H26: =H25/H12 -> -0.0060150947 | I26: =I25/I12 -> -0.011112181 | J26: =J25/J12 -> 0.02 | K26: =K25/K12 -> 0.02 | L26: =L25/L12 -> 0.02 | ... N26: =N25/N12 -> 0.02
B28: Change in NWC | E28: -26 | F28: 1 | G28: -102 | H28: 131 | I28: -33
B29: % of sales | E29: =E28/E12 -> -0.011850393 | F29: =F28/F12 -> 0.00041173952 | G29: =G28/G12 -> -0.041157577 | H29: =H28/H12 -> 0.041472495 | I29: =I28/I12 -> -0.0081489329
A31: x | B31: DCF | E31: 2021 | F31: 2022 | G31: 2023 | H31: 2024 | I31: 2025 | J31: 2026 | K31: 2027 | L31: 2028 | M31: 2029 | N31: 2030
B32: Revenue | E32: =E12 -> 2194.02 | F32: =F12 -> 2428.72 | G32: =G12 -> 2478.28 | H32: =H12 -> 3158.72 | I32: =I12 -> 4049.61 | J32: =I32*(1+J33) -> 4535.5632 | K32: =J32*(1+K33) -> 5125.1864 | L32: =K32*(1+L33) -> 5791.4607 | M32: =L32*(1+M33) -> 6486.4359 | N32: =M32*(1+N33) -> 7199.9439
B33: % growth | F33: =F32/E32-1 -> 0.10697259 | G33: =G32/F32-1 -> 0.02040581 | H33: =H32/G32-1 -> 0.27456139 | I33: =I32/H32-1 -> 0.28204146 | J33: =J13 -> 0.12 | K33: =K13 -> 0.13 | L33: =L13 -> 0.13 | M33: =M13 -> 0.12 | N33: =N13 -> 0.11
B35: EBIT | E35: =E15 -> 1805.59 | F35: =F15 -> 1913.3 | G35: =G15 -> 1929.21 | H35: =H15 -> 2535.83 | I35: =I15 -> 3345.61 | J35: =J32*J36 -> 2857.4048 | K35: =K32*K36 -> 3228.8674 | L35: =L32*L36 -> 3648.6202 | M35: =M32*M36 -> 4086.4546 | N35: =N32*N36 -> 4535.9646
B36: % margin | E36: =E35/E32 -> 0.82295968 | F36: =F35/F32 -> 0.78778122 | G36: =G35/G32 -> 0.77844715 | H36: =H35/H32 -> 0.80280303 | I36: =I35/I32 -> 0.8261561 | J36: =J16 -> 0.63 | K36: =K16 -> 0.63 | L36: =L16 -> 0.63 | M36: =M16 -> 0.63 | N36: =N16 -> 0.63
B38: Taxes | E38: =E18 -> 423.19 | F38: =F18 -> 426.16 | G38: =G18 -> 446.69 | H38: =H18 -> 532.31 | I38: =I18 -> 825.39 | J38: =J35*J39 -> 714.3512 | K38: =K35*K39 -> 807.21686 | L38: =L35*L39 -> 912.15505 | M38: =M35*M39 -> 1021.6137 | N38: =N35*N39 -> 1133.9912
B39: % of EBIT | E39: =E38/E35 -> 0.23437768 | F39: =F38/F35 -> 0.22273559 | G39: =G38/G35 -> 0.23154037 | H39: =H38/H35 -> 0.20991549 | I39: =I38/I35 -> 0.24670837 | J39: =J19 -> 0.25 | K39: =K19 -> 0.25 | L39: =L19 -> 0.25 | M39: =M19 -> 0.25 | N39: =N19 -> 0.25
B41: EBIAT | J41: =J35-J38 -> 2143.0536 | K41: =K35-K38 -> 2421.6506 | L41: =L35-L38 -> 2736.4652 | M41: =M35-M38 -> 3064.841 | N41: =N35-N38 -> 3401.9735
B43: D&A | J43: =J22 -> 90.711264 | K43: =K22 -> 102.50373 | L43: =L22 -> 115.82921 | M43: =M22 -> 129.72872 | N43: =N22 -> 143.99888
B44: % of sales | J44: =J43/J32 -> 0.02 | K44: =K43/K32 -> 0.02 | L44: =L43/L32 -> 0.02 | M44: =M43/M32 -> 0.02 | N44: =N43/N32 -> 0.02
B46: CapEx | J46: =J25 -> 90.711264 | K46: =K25 -> 102.50373 | L46: =L25 -> 115.82921 | M46: =M25 -> 129.72872 | N46: =N25 -> 143.99888
B47: % of sales | J47: =J46/J32 -> 0.02 | K47: =K46/K32 -> 0.02 | L47: =L46/L32 -> 0.02 | M47: =M46/M32 -> 0.02 | N47: =N46/N32 -> 0.02
B49: Change in NWC | J49: =J50*J32 -> -11.84389 | K49: =K50*K32 -> -13.383595 | L49: =L50*L32 -> -15.123463 | M49: =M50*M32 -> -16.938278 | N49: =N50*N32 -> -18.801489
B50: %. of sales | J50: =AVERAGE(G29:I29) -> -0.0026113382 | K50: =AVERAGE(G29:I29) -> -0.0026113382 | L50: =AVERAGE(G29:I29) -> -0.0026113382 | M50: =AVERAGE(G29:I29) -> -0.0026113382 | N50: =AVERAGE(G29:I29) -> -0.0026113382
B52: Unlevered FCF | J52: =J41+J43-J46-J49 -> 2154.8975 | K52: =K41+K43-K46-K49 -> 2435.0342 | L52: =L41+L43-L46-L49 -> 2751.5886 | M52: =M41+M43-M46-M49 -> 3081.7793 | N52: =N41+N43-N46-N49 -> 3420.775
B53: Present Value of FCF | J53: =J52/(1+D8)^J10 -> 1934.5303 | K53: =K52/(1+D8)^K10 -> 1962.4695 | L53: =L52/(1+D8)^L10 -> 1990.8121 | M53: =M52/(1+D8)^M10 -> 2001.6918 | N53: =N52/(1+D8)^N10 -> 1994.6611
A55: x | B55: Terminal Value | N55: =(N52*(1+D9)/(D8-D9)) -> 74482.501
B56: Present Value of Terminal Value | N56: =N55/(1+D8)^N10 -> 43430.904
...

Sheet WACC
A2: x | B2: WACC
B3: WACC = ((% Equity * Cost of Equity) + (% Debt * Cost of Debt * (1-tax rate))
B4: Cost of Equity = Risk Free Rate + (Beta * (Market Rate Premium/Equity Risk Premiuim)
B6: Debt | D6: 0
B7: %Debt | D7: 0.05
B8: Cost of Debt | D8: 0.08
B9: Tax Rate | D9: 0.25
B11: Equity Value | D11: 99111
B12: %Equity | D12: 0.95
B13: Cost of Equity | D13: =D14+(D15*D16) -> 0.11675
B14: Risk Free Rate | D14: 0.07
B15: Beta | D15: 0.85
B16: Market Rate Premiuim | D16: 0.055
B18: Debt + Equity | D18: =D11+D6 -> 99111
A20: x | B20: WACC | D20: =(D12*D13)+(D7*D8*(1-D9)) -> 0.1139125

Sheet Assumptions
A1: REVENEUE ASSUMPTIONS
A2: AUM Growth Rate FY26 | B2: 0.12
A3: AUM Growth Rate FY27 | B3: 0.13
A4: AUM Growth Rate FY28 | B4: 0.13
A5: AUM Growth Rate FY29 | B5: 0.12
A6: AUM Growth Rate FY30 | B6: 0.11
A7: Fee Yield(bps) | B7: 46
A9: MARGIN ASSUMPTIONS
A10: EBIT Margin | B10: 0.63
A11: Depreciation(% of Revenue) | B11: 0.02
A12: Tax Rate | B12: 0.25
A13: Capes(% of revenue) | B13: 0.02
A14: Change in NWC | B14: 0
A16: Terminal Growth Rate | B16: 0.065
